2018-09-21 14:03:08,892 ERROR: Exception on /messages [GET] [in /home/bshi/miniconda3/lib/python3.6/site-packages/flask/app.py:1761]
Traceback (most recent call last):
  File "/home/bshi/miniconda3/lib/python3.6/site-packages/flask/app.py", line 2292, in wsgi_app
    response = self.full_dispatch_request()
  File "/home/bshi/miniconda3/lib/python3.6/site-packages/flask/app.py", line 1815, in full_dispatch_request
    rv = self.handle_user_exception(e)
  File "/home/bshi/miniconda3/lib/python3.6/site-packages/flask/app.py", line 1718, in handle_user_exception
    reraise(exc_type, exc_value, tb)
  File "/home/bshi/miniconda3/lib/python3.6/site-packages/flask/_compat.py", line 35, in reraise
    raise value
  File "/home/bshi/miniconda3/lib/python3.6/site-packages/flask/app.py", line 1813, in full_dispatch_request
    rv = self.dispatch_request()
  File "/home/bshi/miniconda3/lib/python3.6/site-packages/flask/app.py", line 1799, in dispatch_request
    return self.view_functions[rule.endpoint](**req.view_args)
  File "/home/bshi/miniconda3/lib/python3.6/site-packages/flask_login/utils.py", line 261, in decorated_view
    return func(*args, **kwargs)
  File "/mnt/c/Users/Bobby Shi/projects/mangalert/app/main/routes.py", line 165, in messages
    next_url=next_url, prev_url=prev_url)
  File "/home/bshi/miniconda3/lib/python3.6/site-packages/flask/templating.py", line 135, in render_template
    context, ctx.app)
  File "/home/bshi/miniconda3/lib/python3.6/site-packages/flask/templating.py", line 117, in _render
    rv = template.render(context)
  File "/home/bshi/miniconda3/lib/python3.6/site-packages/jinja2/asyncsupport.py", line 76, in render
    return original_render(self, *args, **kwargs)
  File "/home/bshi/miniconda3/lib/python3.6/site-packages/jinja2/environment.py", line 1008, in render
    return self.environment.handle_exception(exc_info, True)
  File "/home/bshi/miniconda3/lib/python3.6/site-packages/jinja2/environment.py", line 780, in handle_exception
    reraise(exc_type, exc_value, tb)
  File "/home/bshi/miniconda3/lib/python3.6/site-packages/jinja2/_compat.py", line 37, in reraise
    raise value.with_traceback(tb)
  File "/mnt/c/Users/Bobby Shi/projects/mangalert/app/templates/messages.html", line 1, in top-level template code
    {% extends "base.html" %}
  File "/mnt/c/Users/Bobby Shi/projects/mangalert/app/templates/base.html", line 1, in top-level template code
    {% extends 'bootstrap/base.html' %}
  File "/home/bshi/miniconda3/lib/python3.6/site-packages/flask_bootstrap/templates/bootstrap/base.html", line 1, in top-level template code
    {% block doc -%}
  File "/home/bshi/miniconda3/lib/python3.6/site-packages/flask_bootstrap/templates/bootstrap/base.html", line 4, in block "doc"
    {%- block html %}
  File "/home/bshi/miniconda3/lib/python3.6/site-packages/flask_bootstrap/templates/bootstrap/base.html", line 20, in block "html"
    {% block body -%}
  File "/home/bshi/miniconda3/lib/python3.6/site-packages/flask_bootstrap/templates/bootstrap/base.html", line 23, in block "body"
    {% block content -%}
  File "/mnt/c/Users/Bobby Shi/projects/mangalert/app/templates/base.html", line 74, in block "content"
    {% block app_content %}{% endblock %}
  File "/mnt/c/Users/Bobby Shi/projects/mangalert/app/templates/messages.html", line 6, in block "app_content"
    {% include '_post.html' %}
  File "/mnt/c/Users/Bobby Shi/projects/mangalert/app/templates/_post.html", line 8, in top-level template code
    <a href="{{ url_for('main.user', username=post.user.username) }}">
  File "/home/bshi/miniconda3/lib/python3.6/site-packages/jinja2/environment.py", line 430, in getattr
    return getattr(obj, attribute)
jinja2.exceptions.UndefinedError: 'app.models.Message object' has no attribute 'user'
2018-09-21 14:04:26,748 INFO: mangalert startup [in /mnt/c/Users/Bobby Shi/projects/mangalert/app/__init__.py:82]
2018-09-21 14:04:33,077 INFO: mangalert startup [in /mnt/c/Users/Bobby Shi/projects/mangalert/app/__init__.py:82]
2018-09-21 14:04:39,470 INFO: mangalert startup [in /mnt/c/Users/Bobby Shi/projects/mangalert/app/__init__.py:82]
2018-09-21 16:08:07,245 INFO: mangalert startup [in /mnt/c/Users/Bobby Shi/projects/mangalert/app/__init__.py:82]
2018-09-21 16:35:05,344 INFO: mangalert startup [in /mnt/c/Users/Bobby Shi/projects/mangalert/app/__init__.py:82]
2018-09-21 16:41:34,073 INFO: mangalert startup [in /mnt/c/Users/Bobby Shi/projects/mangalert/app/__init__.py:82]
2018-09-21 16:48:01,923 INFO: mangalert startup [in /mnt/c/Users/Bobby Shi/projects/mangalert/app/__init__.py:82]
2018-09-21 16:48:27,934 ERROR: Exception on /follows [GET] [in /home/bshi/miniconda3/lib/python3.6/site-packages/flask/app.py:1761]
Traceback (most recent call last):
  File "/home/bshi/miniconda3/lib/python3.6/site-packages/flask/app.py", line 2292, in wsgi_app
    response = self.full_dispatch_request()
  File "/home/bshi/miniconda3/lib/python3.6/site-packages/flask/app.py", line 1815, in full_dispatch_request
    rv = self.handle_user_exception(e)
  File "/home/bshi/miniconda3/lib/python3.6/site-packages/flask/app.py", line 1718, in handle_user_exception
    reraise(exc_type, exc_value, tb)
  File "/home/bshi/miniconda3/lib/python3.6/site-packages/flask/_compat.py", line 35, in reraise
    raise value
  File "/home/bshi/miniconda3/lib/python3.6/site-packages/flask/app.py", line 1813, in full_dispatch_request
    rv = self.dispatch_request()
  File "/home/bshi/miniconda3/lib/python3.6/site-packages/flask/app.py", line 1799, in dispatch_request
    return self.view_functions[rule.endpoint](**req.view_args)
  File "/home/bshi/miniconda3/lib/python3.6/site-packages/flask_login/utils.py", line 261, in decorated_view
    return func(*args, **kwargs)
  File "/mnt/c/Users/Bobby Shi/projects/mangalert/app/main/routes.py", line 184, in follows
    ongoing = Manga.query.join(Manga.followers).filter(User==current_user, Manga.ongoing==True).all()
NameError: name 'Manga' is not defined
2018-09-21 16:49:15,686 INFO: mangalert startup [in /mnt/c/Users/Bobby Shi/projects/mangalert/app/__init__.py:82]
