2018-09-19 14:17:09,842 ERROR: Exception on /user/admin [GET] [in /home/bshi/miniconda3/lib/python3.6/site-packages/flask/app.py:1761]
Traceback (most recent call last):
  File "/home/bshi/miniconda3/lib/python3.6/site-packages/flask/app.py", line 2292, in wsgi_app
    response = self.full_dispatch_request()
  File "/home/bshi/miniconda3/lib/python3.6/site-packages/flask/app.py", line 1815, in full_dispatch_request
    rv = self.handle_user_exception(e)
  File "/home/bshi/miniconda3/lib/python3.6/site-packages/flask/app.py", line 1718, in handle_user_exception
    reraise(exc_type, exc_value, tb)
  File "/home/bshi/miniconda3/lib/python3.6/site-packages/flask/_compat.py", line 35, in reraise
    raise value
  File "/home/bshi/miniconda3/lib/python3.6/site-packages/flask/app.py", line 1813, in full_dispatch_request
    rv = self.dispatch_request()
  File "/home/bshi/miniconda3/lib/python3.6/site-packages/flask/app.py", line 1799, in dispatch_request
    return self.view_functions[rule.endpoint](**req.view_args)
  File "/home/bshi/miniconda3/lib/python3.6/site-packages/flask_login/utils.py", line 261, in decorated_view
    return func(*args, **kwargs)
  File "/mnt/c/Users/Bobby Shi/projects/mangalert/app/main/routes.py", line 76, in user
    next_url=next_url, prev_url=prev_url)
  File "/home/bshi/miniconda3/lib/python3.6/site-packages/flask/templating.py", line 135, in render_template
    context, ctx.app)
  File "/home/bshi/miniconda3/lib/python3.6/site-packages/flask/templating.py", line 117, in _render
    rv = template.render(context)
  File "/home/bshi/miniconda3/lib/python3.6/site-packages/jinja2/asyncsupport.py", line 76, in render
    return original_render(self, *args, **kwargs)
  File "/home/bshi/miniconda3/lib/python3.6/site-packages/jinja2/environment.py", line 1008, in render
    return self.environment.handle_exception(exc_info, True)
  File "/home/bshi/miniconda3/lib/python3.6/site-packages/jinja2/environment.py", line 780, in handle_exception
    reraise(exc_type, exc_value, tb)
  File "/home/bshi/miniconda3/lib/python3.6/site-packages/jinja2/_compat.py", line 37, in reraise
    raise value.with_traceback(tb)
  File "/mnt/c/Users/Bobby Shi/projects/mangalert/app/templates/user.html", line 2, in top-level template code
    {% import 'bootstrap/wtf.html' as wtf %}
  File "/mnt/c/Users/Bobby Shi/projects/mangalert/app/templates/base.html", line 1, in top-level template code
    {% extends 'bootstrap/base.html' %}
  File "/home/bshi/miniconda3/lib/python3.6/site-packages/flask_bootstrap/templates/bootstrap/base.html", line 1, in top-level template code
    {% block doc -%}
  File "/home/bshi/miniconda3/lib/python3.6/site-packages/flask_bootstrap/templates/bootstrap/base.html", line 4, in block "doc"
    {%- block html %}
  File "/home/bshi/miniconda3/lib/python3.6/site-packages/flask_bootstrap/templates/bootstrap/base.html", line 20, in block "html"
    {% block body -%}
  File "/home/bshi/miniconda3/lib/python3.6/site-packages/flask_bootstrap/templates/bootstrap/base.html", line 23, in block "body"
    {% block content -%}
  File "/mnt/c/Users/Bobby Shi/projects/mangalert/app/templates/base.html", line 53, in block "content"
    {% block app_content %}{% endblock %}
  File "/mnt/c/Users/Bobby Shi/projects/mangalert/app/templates/user.html", line 14, in block "app_content"
    <p>{{ '{} followers'.format(count=user.followers.count()) }}, {{ '{} following'.format(count=user.followed.count()) }}</p>
IndexError: tuple index out of range
2018-09-19 14:17:30,662 INFO: mangalert startup [in /mnt/c/Users/Bobby Shi/projects/mangalert/app/__init__.py:76]
2018-09-19 14:17:32,034 ERROR: Exception on /user/admin [GET] [in /home/bshi/miniconda3/lib/python3.6/site-packages/flask/app.py:1761]
Traceback (most recent call last):
  File "/home/bshi/miniconda3/lib/python3.6/site-packages/flask/app.py", line 2292, in wsgi_app
    response = self.full_dispatch_request()
  File "/home/bshi/miniconda3/lib/python3.6/site-packages/flask/app.py", line 1815, in full_dispatch_request
    rv = self.handle_user_exception(e)
  File "/home/bshi/miniconda3/lib/python3.6/site-packages/flask/app.py", line 1718, in handle_user_exception
    reraise(exc_type, exc_value, tb)
  File "/home/bshi/miniconda3/lib/python3.6/site-packages/flask/_compat.py", line 35, in reraise
    raise value
  File "/home/bshi/miniconda3/lib/python3.6/site-packages/flask/app.py", line 1813, in full_dispatch_request
    rv = self.dispatch_request()
  File "/home/bshi/miniconda3/lib/python3.6/site-packages/flask/app.py", line 1799, in dispatch_request
    return self.view_functions[rule.endpoint](**req.view_args)
  File "/home/bshi/miniconda3/lib/python3.6/site-packages/flask_login/utils.py", line 261, in decorated_view
    return func(*args, **kwargs)
  File "/mnt/c/Users/Bobby Shi/projects/mangalert/app/main/routes.py", line 76, in user
    next_url=next_url, prev_url=prev_url)
  File "/home/bshi/miniconda3/lib/python3.6/site-packages/flask/templating.py", line 135, in render_template
    context, ctx.app)
  File "/home/bshi/miniconda3/lib/python3.6/site-packages/flask/templating.py", line 117, in _render
    rv = template.render(context)
  File "/home/bshi/miniconda3/lib/python3.6/site-packages/jinja2/asyncsupport.py", line 76, in render
    return original_render(self, *args, **kwargs)
  File "/home/bshi/miniconda3/lib/python3.6/site-packages/jinja2/environment.py", line 1008, in render
    return self.environment.handle_exception(exc_info, True)
  File "/home/bshi/miniconda3/lib/python3.6/site-packages/jinja2/environment.py", line 780, in handle_exception
    reraise(exc_type, exc_value, tb)
  File "/home/bshi/miniconda3/lib/python3.6/site-packages/jinja2/_compat.py", line 37, in reraise
    raise value.with_traceback(tb)
  File "/mnt/c/Users/Bobby Shi/projects/mangalert/app/templates/user.html", line 2, in top-level template code
    {% import 'bootstrap/wtf.html' as wtf %}
  File "/mnt/c/Users/Bobby Shi/projects/mangalert/app/templates/base.html", line 1, in top-level template code
    {% extends 'bootstrap/base.html' %}
  File "/home/bshi/miniconda3/lib/python3.6/site-packages/flask_bootstrap/templates/bootstrap/base.html", line 1, in top-level template code
    {% block doc -%}
  File "/home/bshi/miniconda3/lib/python3.6/site-packages/flask_bootstrap/templates/bootstrap/base.html", line 4, in block "doc"
    {%- block html %}
  File "/home/bshi/miniconda3/lib/python3.6/site-packages/flask_bootstrap/templates/bootstrap/base.html", line 20, in block "html"
    {% block body -%}
  File "/home/bshi/miniconda3/lib/python3.6/site-packages/flask_bootstrap/templates/bootstrap/base.html", line 23, in block "body"
    {% block content -%}
  File "/mnt/c/Users/Bobby Shi/projects/mangalert/app/templates/base.html", line 53, in block "content"
    {% block app_content %}{% endblock %}
  File "/mnt/c/Users/Bobby Shi/projects/mangalert/app/templates/user.html", line 14, in block "app_content"
    <p>{{ '{} followers'.format(user.followers.count()) }}, {{ '{} following'.format(user.followed.count()) }}</p>
  File "/home/bshi/miniconda3/lib/python3.6/site-packages/jinja2/environment.py", line 430, in getattr
    return getattr(obj, attribute)
jinja2.exceptions.UndefinedError: 'app.models.User object' has no attribute 'followed'
2018-09-19 14:18:16,194 INFO: mangalert startup [in /mnt/c/Users/Bobby Shi/projects/mangalert/app/__init__.py:76]
2018-09-19 14:19:32,274 INFO: mangalert startup [in /mnt/c/Users/Bobby Shi/projects/mangalert/app/__init__.py:76]
