2018-09-21 13:55:36,003 ERROR: Exception on /notifications [GET] [in /home/bshi/miniconda3/lib/python3.6/site-packages/flask/app.py:1761]
Traceback (most recent call last):
  File "/home/bshi/miniconda3/lib/python3.6/site-packages/flask/app.py", line 2292, in wsgi_app
    response = self.full_dispatch_request()
  File "/home/bshi/miniconda3/lib/python3.6/site-packages/flask/app.py", line 1815, in full_dispatch_request
    rv = self.handle_user_exception(e)
  File "/home/bshi/miniconda3/lib/python3.6/site-packages/flask/app.py", line 1718, in handle_user_exception
    reraise(exc_type, exc_value, tb)
  File "/home/bshi/miniconda3/lib/python3.6/site-packages/flask/_compat.py", line 35, in reraise
    raise value
  File "/home/bshi/miniconda3/lib/python3.6/site-packages/flask/app.py", line 1813, in full_dispatch_request
    rv = self.dispatch_request()
  File "/home/bshi/miniconda3/lib/python3.6/site-packages/flask/app.py", line 1799, in dispatch_request
    return self.view_functions[rule.endpoint](**req.view_args)
  File "/home/bshi/miniconda3/lib/python3.6/site-packages/flask_login/utils.py", line 261, in decorated_view
    return func(*args, **kwargs)
  File "/mnt/c/Users/Bobby Shi/projects/mangalert/app/main/routes.py", line 174, in notifications
    return jsonify([{
NameError: name 'jsonify' is not defined
2018-09-21 13:55:45,861 ERROR: Exception on /notifications [GET] [in /home/bshi/miniconda3/lib/python3.6/site-packages/flask/app.py:1761]
Traceback (most recent call last):
  File "/home/bshi/miniconda3/lib/python3.6/site-packages/flask/app.py", line 2292, in wsgi_app
    response = self.full_dispatch_request()
  File "/home/bshi/miniconda3/lib/python3.6/site-packages/flask/app.py", line 1815, in full_dispatch_request
    rv = self.handle_user_exception(e)
  File "/home/bshi/miniconda3/lib/python3.6/site-packages/flask/app.py", line 1718, in handle_user_exception
    reraise(exc_type, exc_value, tb)
  File "/home/bshi/miniconda3/lib/python3.6/site-packages/flask/_compat.py", line 35, in reraise
    raise value
  File "/home/bshi/miniconda3/lib/python3.6/site-packages/flask/app.py", line 1813, in full_dispatch_request
    rv = self.dispatch_request()
  File "/home/bshi/miniconda3/lib/python3.6/site-packages/flask/app.py", line 1799, in dispatch_request
    return self.view_functions[rule.endpoint](**req.view_args)
  File "/home/bshi/miniconda3/lib/python3.6/site-packages/flask_login/utils.py", line 261, in decorated_view
    return func(*args, **kwargs)
  File "/mnt/c/Users/Bobby Shi/projects/mangalert/app/main/routes.py", line 174, in notifications
    return jsonify([{
NameError: name 'jsonify' is not defined
2018-09-21 13:56:02,084 INFO: mangalert startup [in /mnt/c/Users/Bobby Shi/projects/mangalert/app/__init__.py:82]
2018-09-21 13:56:35,883 INFO: mangalert startup [in /mnt/c/Users/Bobby Shi/projects/mangalert/app/__init__.py:82]
2018-09-21 13:58:00,975 INFO: mangalert startup [in /mnt/c/Users/Bobby Shi/projects/mangalert/app/__init__.py:82]
2018-09-21 13:58:32,745 ERROR: Exception on /user/admin [POST] [in /home/bshi/miniconda3/lib/python3.6/site-packages/flask/app.py:1761]
Traceback (most recent call last):
  File "/home/bshi/miniconda3/lib/python3.6/site-packages/flask/app.py", line 2292, in wsgi_app
    response = self.full_dispatch_request()
  File "/home/bshi/miniconda3/lib/python3.6/site-packages/flask/app.py", line 1815, in full_dispatch_request
    rv = self.handle_user_exception(e)
  File "/home/bshi/miniconda3/lib/python3.6/site-packages/flask/app.py", line 1718, in handle_user_exception
    reraise(exc_type, exc_value, tb)
  File "/home/bshi/miniconda3/lib/python3.6/site-packages/flask/_compat.py", line 35, in reraise
    raise value
  File "/home/bshi/miniconda3/lib/python3.6/site-packages/flask/app.py", line 1813, in full_dispatch_request
    rv = self.dispatch_request()
  File "/home/bshi/miniconda3/lib/python3.6/site-packages/flask/app.py", line 1799, in dispatch_request
    return self.view_functions[rule.endpoint](**req.view_args)
  File "/home/bshi/miniconda3/lib/python3.6/site-packages/flask_login/utils.py", line 261, in decorated_view
    return func(*args, **kwargs)
  File "/mnt/c/Users/Bobby Shi/projects/mangalert/app/main/routes.py", line 69, in user
    current_user.launch_task('get_follows', 'getting follows...')
  File "/mnt/c/Users/Bobby Shi/projects/mangalert/app/models.py", line 106, in launch_task
    rq_job = current_app.task_queue.enqueue('app.tasks.' + name, self.id,
NameError: name 'current_app' is not defined
2018-09-21 13:59:13,125 INFO: mangalert startup [in /mnt/c/Users/Bobby Shi/projects/mangalert/app/__init__.py:82]
2018-09-21 13:59:29,249 INFO: mangalert startup [in ./app/__init__.py:82]
2018-09-21 14:02:07,117 ERROR: Exception on /send_message/admin [GET] [in /home/bshi/miniconda3/lib/python3.6/site-packages/flask/app.py:1761]
Traceback (most recent call last):
  File "/home/bshi/miniconda3/lib/python3.6/site-packages/flask/app.py", line 2292, in wsgi_app
    response = self.full_dispatch_request()
  File "/home/bshi/miniconda3/lib/python3.6/site-packages/flask/app.py", line 1815, in full_dispatch_request
    rv = self.handle_user_exception(e)
  File "/home/bshi/miniconda3/lib/python3.6/site-packages/flask/app.py", line 1718, in handle_user_exception
    reraise(exc_type, exc_value, tb)
  File "/home/bshi/miniconda3/lib/python3.6/site-packages/flask/_compat.py", line 35, in reraise
    raise value
  File "/home/bshi/miniconda3/lib/python3.6/site-packages/flask/app.py", line 1813, in full_dispatch_request
    rv = self.dispatch_request()
  File "/home/bshi/miniconda3/lib/python3.6/site-packages/flask/app.py", line 1799, in dispatch_request
    return self.view_functions[rule.endpoint](**req.view_args)
  File "/home/bshi/miniconda3/lib/python3.6/site-packages/flask_login/utils.py", line 261, in decorated_view
    return func(*args, **kwargs)
  File "/mnt/c/Users/Bobby Shi/projects/mangalert/app/main/routes.py", line 146, in send_message
    form=form, recipient=recipient)
  File "/home/bshi/miniconda3/lib/python3.6/site-packages/flask/templating.py", line 134, in render_template
    return _render(ctx.app.jinja_env.get_or_select_template(template_name_or_list),
  File "/home/bshi/miniconda3/lib/python3.6/site-packages/jinja2/environment.py", line 869, in get_or_select_template
    return self.get_template(template_name_or_list, parent, globals)
  File "/home/bshi/miniconda3/lib/python3.6/site-packages/jinja2/environment.py", line 830, in get_template
    return self._load_template(name, self.make_globals(globals))
  File "/home/bshi/miniconda3/lib/python3.6/site-packages/jinja2/environment.py", line 804, in _load_template
    template = self.loader.load(self, name, globals)
  File "/home/bshi/miniconda3/lib/python3.6/site-packages/jinja2/loaders.py", line 113, in load
    source, filename, uptodate = self.get_source(environment, name)
  File "/home/bshi/miniconda3/lib/python3.6/site-packages/flask/templating.py", line 58, in get_source
    return self._get_source_fast(environment, template)
  File "/home/bshi/miniconda3/lib/python3.6/site-packages/flask/templating.py", line 86, in _get_source_fast
    raise TemplateNotFound(template)
jinja2.exceptions.TemplateNotFound: send_message.html
2018-09-21 14:02:34,743 INFO: mangalert startup [in /mnt/c/Users/Bobby Shi/projects/mangalert/app/__init__.py:82]
