2018-09-18 16:02:59,980 ERROR: Exception on / [GET] [in /home/bshi/miniconda3/lib/python3.6/site-packages/flask/app.py:1761]
Traceback (most recent call last):
  File "/home/bshi/miniconda3/lib/python3.6/site-packages/flask/app.py", line 2292, in wsgi_app
    response = self.full_dispatch_request()
  File "/home/bshi/miniconda3/lib/python3.6/site-packages/flask/app.py", line 1815, in full_dispatch_request
    rv = self.handle_user_exception(e)
  File "/home/bshi/miniconda3/lib/python3.6/site-packages/flask/app.py", line 1718, in handle_user_exception
    reraise(exc_type, exc_value, tb)
  File "/home/bshi/miniconda3/lib/python3.6/site-packages/flask/_compat.py", line 35, in reraise
    raise value
  File "/home/bshi/miniconda3/lib/python3.6/site-packages/flask/app.py", line 1813, in full_dispatch_request
    rv = self.dispatch_request()
  File "/home/bshi/miniconda3/lib/python3.6/site-packages/flask/app.py", line 1799, in dispatch_request
    return self.view_functions[rule.endpoint](**req.view_args)
  File "/home/bshi/miniconda3/lib/python3.6/site-packages/flask_login/utils.py", line 261, in decorated_view
    return func(*args, **kwargs)
  File "/mnt/c/Users/Bobby Shi/projects/mangalert/app/routes.py", line 25, in index
    return render_template('index.html', form=form, posts=posts)
  File "/home/bshi/miniconda3/lib/python3.6/site-packages/flask/templating.py", line 135, in render_template
    context, ctx.app)
  File "/home/bshi/miniconda3/lib/python3.6/site-packages/flask/templating.py", line 117, in _render
    rv = template.render(context)
  File "/home/bshi/miniconda3/lib/python3.6/site-packages/jinja2/asyncsupport.py", line 76, in render
    return original_render(self, *args, **kwargs)
  File "/home/bshi/miniconda3/lib/python3.6/site-packages/jinja2/environment.py", line 1008, in render
    return self.environment.handle_exception(exc_info, True)
  File "/home/bshi/miniconda3/lib/python3.6/site-packages/jinja2/environment.py", line 780, in handle_exception
    reraise(exc_type, exc_value, tb)
  File "/home/bshi/miniconda3/lib/python3.6/site-packages/jinja2/_compat.py", line 37, in reraise
    raise value.with_traceback(tb)
  File "/mnt/c/Users/Bobby Shi/projects/mangalert/app/templates/index.html", line 1, in top-level template code
    {% extends "base.html" %}
  File "/mnt/c/Users/Bobby Shi/projects/mangalert/app/templates/base.html", line 33, in top-level template code
    {% block content %}{% endblock %}
  File "/mnt/c/Users/Bobby Shi/projects/mangalert/app/templates/index.html", line 15, in block "content"
    {{ form.link(32) }}<br>
TypeError: __call__() takes 1 positional argument but 2 were given
2018-09-18 16:03:32,905 INFO: Microblog startup [in /mnt/c/Users/Bobby Shi/projects/mangalert/app/__init__.py:46]
2018-09-18 16:06:10,711 INFO: Microblog startup [in /mnt/c/Users/Bobby Shi/projects/mangalert/app/__init__.py:46]
2018-09-18 16:06:15,123 ERROR: Exception on / [GET] [in /home/bshi/miniconda3/lib/python3.6/site-packages/flask/app.py:1761]
Traceback (most recent call last):
  File "/home/bshi/miniconda3/lib/python3.6/site-packages/flask/app.py", line 2292, in wsgi_app
    response = self.full_dispatch_request()
  File "/home/bshi/miniconda3/lib/python3.6/site-packages/flask/app.py", line 1815, in full_dispatch_request
    rv = self.handle_user_exception(e)
  File "/home/bshi/miniconda3/lib/python3.6/site-packages/flask/app.py", line 1718, in handle_user_exception
    reraise(exc_type, exc_value, tb)
  File "/home/bshi/miniconda3/lib/python3.6/site-packages/flask/_compat.py", line 35, in reraise
    raise value
  File "/home/bshi/miniconda3/lib/python3.6/site-packages/flask/app.py", line 1813, in full_dispatch_request
    rv = self.dispatch_request()
  File "/home/bshi/miniconda3/lib/python3.6/site-packages/flask/app.py", line 1799, in dispatch_request
    return self.view_functions[rule.endpoint](**req.view_args)
  File "/home/bshi/miniconda3/lib/python3.6/site-packages/flask_login/utils.py", line 261, in decorated_view
    return func(*args, **kwargs)
  File "/mnt/c/Users/Bobby Shi/projects/mangalert/app/routes.py", line 24, in index
    posts = current_user.followed_posts().all()
  File "/mnt/c/Users/Bobby Shi/projects/mangalert/app/models.py", line 65, in followed_posts
    own = Post.query.filter_by(user_id==self.id)
NameError: name 'user_id' is not defined
2018-09-18 16:07:03,740 INFO: Microblog startup [in /mnt/c/Users/Bobby Shi/projects/mangalert/app/__init__.py:46]
2018-09-18 16:07:06,598 ERROR: Exception on / [GET] [in /home/bshi/miniconda3/lib/python3.6/site-packages/flask/app.py:1761]
Traceback (most recent call last):
  File "/home/bshi/miniconda3/lib/python3.6/site-packages/flask/app.py", line 2292, in wsgi_app
    response = self.full_dispatch_request()
  File "/home/bshi/miniconda3/lib/python3.6/site-packages/flask/app.py", line 1815, in full_dispatch_request
    rv = self.handle_user_exception(e)
  File "/home/bshi/miniconda3/lib/python3.6/site-packages/flask/app.py", line 1718, in handle_user_exception
    reraise(exc_type, exc_value, tb)
  File "/home/bshi/miniconda3/lib/python3.6/site-packages/flask/_compat.py", line 35, in reraise
    raise value
  File "/home/bshi/miniconda3/lib/python3.6/site-packages/flask/app.py", line 1813, in full_dispatch_request
    rv = self.dispatch_request()
  File "/home/bshi/miniconda3/lib/python3.6/site-packages/flask/app.py", line 1799, in dispatch_request
    return self.view_functions[rule.endpoint](**req.view_args)
  File "/home/bshi/miniconda3/lib/python3.6/site-packages/flask_login/utils.py", line 261, in decorated_view
    return func(*args, **kwargs)
  File "/mnt/c/Users/Bobby Shi/projects/mangalert/app/routes.py", line 24, in index
    posts = current_user.followed_posts().all()
  File "/mnt/c/Users/Bobby Shi/projects/mangalert/app/models.py", line 65, in followed_posts
    own = Post.query.filter_by(Post.user_id==self.id)
TypeError: filter_by() takes 1 positional argument but 2 were given
2018-09-18 16:08:31,482 INFO: Microblog startup [in /mnt/c/Users/Bobby Shi/projects/mangalert/app/__init__.py:46]
2018-09-18 16:08:33,196 ERROR: Exception on / [GET] [in /home/bshi/miniconda3/lib/python3.6/site-packages/flask/app.py:1761]
Traceback (most recent call last):
  File "/home/bshi/miniconda3/lib/python3.6/site-packages/flask/app.py", line 2292, in wsgi_app
    response = self.full_dispatch_request()
  File "/home/bshi/miniconda3/lib/python3.6/site-packages/flask/app.py", line 1815, in full_dispatch_request
    rv = self.handle_user_exception(e)
  File "/home/bshi/miniconda3/lib/python3.6/site-packages/flask/app.py", line 1718, in handle_user_exception
    reraise(exc_type, exc_value, tb)
  File "/home/bshi/miniconda3/lib/python3.6/site-packages/flask/_compat.py", line 35, in reraise
    raise value
  File "/home/bshi/miniconda3/lib/python3.6/site-packages/flask/app.py", line 1813, in full_dispatch_request
    rv = self.dispatch_request()
  File "/home/bshi/miniconda3/lib/python3.6/site-packages/flask/app.py", line 1799, in dispatch_request
    return self.view_functions[rule.endpoint](**req.view_args)
  File "/home/bshi/miniconda3/lib/python3.6/site-packages/flask_login/utils.py", line 261, in decorated_view
    return func(*args, **kwargs)
  File "/mnt/c/Users/Bobby Shi/projects/mangalert/app/routes.py", line 24, in index
    posts = current_user.followed_posts().all()
  File "/mnt/c/Users/Bobby Shi/projects/mangalert/app/models.py", line 65, in followed_posts
    own = Post.query.filter_by(user_id==self.id)
NameError: name 'user_id' is not defined
2018-09-18 16:08:57,561 INFO: Microblog startup [in /mnt/c/Users/Bobby Shi/projects/mangalert/app/__init__.py:46]
2018-09-18 16:09:00,400 ERROR: Exception on / [GET] [in /home/bshi/miniconda3/lib/python3.6/site-packages/flask/app.py:1761]
Traceback (most recent call last):
  File "/home/bshi/miniconda3/lib/python3.6/site-packages/flask/app.py", line 2292, in wsgi_app
    response = self.full_dispatch_request()
  File "/home/bshi/miniconda3/lib/python3.6/site-packages/flask/app.py", line 1815, in full_dispatch_request
    rv = self.handle_user_exception(e)
  File "/home/bshi/miniconda3/lib/python3.6/site-packages/flask/app.py", line 1718, in handle_user_exception
    reraise(exc_type, exc_value, tb)
  File "/home/bshi/miniconda3/lib/python3.6/site-packages/flask/_compat.py", line 35, in reraise
    raise value
  File "/home/bshi/miniconda3/lib/python3.6/site-packages/flask/app.py", line 1813, in full_dispatch_request
    rv = self.dispatch_request()
  File "/home/bshi/miniconda3/lib/python3.6/site-packages/flask/app.py", line 1799, in dispatch_request
    return self.view_functions[rule.endpoint](**req.view_args)
  File "/home/bshi/miniconda3/lib/python3.6/site-packages/flask_login/utils.py", line 261, in decorated_view
    return func(*args, **kwargs)
  File "/mnt/c/Users/Bobby Shi/projects/mangalert/app/routes.py", line 24, in index
    posts = current_user.followed_posts().all()
  File "/mnt/c/Users/Bobby Shi/projects/mangalert/app/models.py", line 65, in followed_posts
    own = Post.query.filter_by(user_id==self.id)
NameError: name 'user_id' is not defined
2018-09-18 16:09:23,411 INFO: Microblog startup [in /mnt/c/Users/Bobby Shi/projects/mangalert/app/__init__.py:46]
