2018-09-18 18:08:34,890 ERROR: Exception on / [GET] [in /home/bshi/miniconda3/lib/python3.6/site-packages/flask/app.py:1761]
Traceback (most recent call last):
  File "/home/bshi/miniconda3/lib/python3.6/site-packages/sqlalchemy/engine/base.py", line 1193, in _execute_context
    context)
  File "/home/bshi/miniconda3/lib/python3.6/site-packages/sqlalchemy/engine/default.py", line 509, in do_execute
    cursor.execute(statement, parameters)
sqlite3.OperationalError: no such table: user

The above exception was the direct cause of the following exception:

Traceback (most recent call last):
  File "/home/bshi/miniconda3/lib/python3.6/site-packages/flask/app.py", line 2292, in wsgi_app
    response = self.full_dispatch_request()
  File "/home/bshi/miniconda3/lib/python3.6/site-packages/flask/app.py", line 1815, in full_dispatch_request
    rv = self.handle_user_exception(e)
  File "/home/bshi/miniconda3/lib/python3.6/site-packages/flask/app.py", line 1718, in handle_user_exception
    reraise(exc_type, exc_value, tb)
  File "/home/bshi/miniconda3/lib/python3.6/site-packages/flask/_compat.py", line 35, in reraise
    raise value
  File "/home/bshi/miniconda3/lib/python3.6/site-packages/flask/app.py", line 1811, in full_dispatch_request
    rv = self.preprocess_request()
  File "/home/bshi/miniconda3/lib/python3.6/site-packages/flask/app.py", line 2087, in preprocess_request
    rv = func()
  File "/mnt/c/Users/Bobby Shi/projects/mangalert/app/routes.py", line 96, in before_request
    if current_user.is_authenticated:
  File "/home/bshi/miniconda3/lib/python3.6/site-packages/werkzeug/local.py", line 347, in __getattr__
    return getattr(self._get_current_object(), name)
  File "/home/bshi/miniconda3/lib/python3.6/site-packages/werkzeug/local.py", line 306, in _get_current_object
    return self.__local()
  File "/home/bshi/miniconda3/lib/python3.6/site-packages/flask_login/utils.py", line 26, in <lambda>
    current_user = LocalProxy(lambda: _get_user())
  File "/home/bshi/miniconda3/lib/python3.6/site-packages/flask_login/utils.py", line 335, in _get_user
    current_app.login_manager._load_user()
  File "/home/bshi/miniconda3/lib/python3.6/site-packages/flask_login/login_manager.py", line 359, in _load_user
    return self.reload_user()
  File "/home/bshi/miniconda3/lib/python3.6/site-packages/flask_login/login_manager.py", line 321, in reload_user
    user = self.user_callback(user_id)
  File "/mnt/c/Users/Bobby Shi/projects/mangalert/app/models.py", line 95, in load_user
    return User.query.get(int(id))
  File "/home/bshi/miniconda3/lib/python3.6/site-packages/sqlalchemy/orm/query.py", line 923, in get
    ident, loading.load_on_pk_identity)
  File "/home/bshi/miniconda3/lib/python3.6/site-packages/sqlalchemy/orm/query.py", line 1006, in _get_impl
    return db_load_fn(self, primary_key_identity)
  File "/home/bshi/miniconda3/lib/python3.6/site-packages/sqlalchemy/orm/loading.py", line 250, in load_on_pk_identity
    return q.one()
  File "/home/bshi/miniconda3/lib/python3.6/site-packages/sqlalchemy/orm/query.py", line 2947, in one
    ret = self.one_or_none()
  File "/home/bshi/miniconda3/lib/python3.6/site-packages/sqlalchemy/orm/query.py", line 2917, in one_or_none
    ret = list(self)
  File "/home/bshi/miniconda3/lib/python3.6/site-packages/sqlalchemy/orm/query.py", line 2988, in __iter__
    return self._execute_and_instances(context)
  File "/home/bshi/miniconda3/lib/python3.6/site-packages/sqlalchemy/orm/query.py", line 3011, in _execute_and_instances
    result = conn.execute(querycontext.statement, self._params)
  File "/home/bshi/miniconda3/lib/python3.6/site-packages/sqlalchemy/engine/base.py", line 948, in execute
    return meth(self, multiparams, params)
  File "/home/bshi/miniconda3/lib/python3.6/site-packages/sqlalchemy/sql/elements.py", line 269, in _execute_on_connection
    return connection._execute_clauseelement(self, multiparams, params)
  File "/home/bshi/miniconda3/lib/python3.6/site-packages/sqlalchemy/engine/base.py", line 1060, in _execute_clauseelement
    compiled_sql, distilled_params
  File "/home/bshi/miniconda3/lib/python3.6/site-packages/sqlalchemy/engine/base.py", line 1200, in _execute_context
    context)
  File "/home/bshi/miniconda3/lib/python3.6/site-packages/sqlalchemy/engine/base.py", line 1413, in _handle_dbapi_exception
    exc_info
  File "/home/bshi/miniconda3/lib/python3.6/site-packages/sqlalchemy/util/compat.py", line 265, in raise_from_cause
    reraise(type(exception), exception, tb=exc_tb, cause=cause)
  File "/home/bshi/miniconda3/lib/python3.6/site-packages/sqlalchemy/util/compat.py", line 248, in reraise
    raise value.with_traceback(tb)
  File "/home/bshi/miniconda3/lib/python3.6/site-packages/sqlalchemy/engine/base.py", line 1193, in _execute_context
    context)
  File "/home/bshi/miniconda3/lib/python3.6/site-packages/sqlalchemy/engine/default.py", line 509, in do_execute
    cursor.execute(statement, parameters)
sqlalchemy.exc.OperationalError: (sqlite3.OperationalError) no such table: user [SQL: 'SELECT user.id AS user_id, user.username AS user_username, user.email AS user_email, user.password_hash AS user_password_hash, user.mdlist AS user_mdlist, user.about_me AS user_about_me, user.last_seen AS user_last_seen \nFROM user \nWHERE user.id = ?'] [parameters: (1,)] (Background on this error at: http://sqlalche.me/e/e3q8)
2018-09-18 18:08:45,186 INFO: Microblog startup [in /mnt/c/Users/Bobby Shi/projects/mangalert/app/__init__.py:46]
2018-09-18 18:09:05,218 INFO: Microblog startup [in /mnt/c/Users/Bobby Shi/projects/mangalert/app/__init__.py:46]
2018-09-18 18:09:35,665 INFO: Microblog startup [in /mnt/c/Users/Bobby Shi/projects/mangalert/app/__init__.py:46]
2018-09-18 18:09:42,463 INFO: Microblog startup [in /mnt/c/Users/Bobby Shi/projects/mangalert/app/__init__.py:46]
2018-09-18 18:09:48,987 INFO: Microblog startup [in /mnt/c/Users/Bobby Shi/projects/mangalert/app/__init__.py:46]
2018-09-18 18:11:48,406 ERROR: Exception on /user/admin [GET] [in /home/bshi/miniconda3/lib/python3.6/site-packages/flask/app.py:1761]
Traceback (most recent call last):
  File "/home/bshi/miniconda3/lib/python3.6/site-packages/flask/app.py", line 2292, in wsgi_app
    response = self.full_dispatch_request()
  File "/home/bshi/miniconda3/lib/python3.6/site-packages/flask/app.py", line 1815, in full_dispatch_request
    rv = self.handle_user_exception(e)
  File "/home/bshi/miniconda3/lib/python3.6/site-packages/flask/app.py", line 1718, in handle_user_exception
    reraise(exc_type, exc_value, tb)
  File "/home/bshi/miniconda3/lib/python3.6/site-packages/flask/_compat.py", line 35, in reraise
    raise value
  File "/home/bshi/miniconda3/lib/python3.6/site-packages/flask/app.py", line 1813, in full_dispatch_request
    rv = self.dispatch_request()
  File "/home/bshi/miniconda3/lib/python3.6/site-packages/flask/app.py", line 1799, in dispatch_request
    return self.view_functions[rule.endpoint](**req.view_args)
  File "/home/bshi/miniconda3/lib/python3.6/site-packages/flask_login/utils.py", line 261, in decorated_view
    return func(*args, **kwargs)
  File "/mnt/c/Users/Bobby Shi/projects/mangalert/app/routes.py", line 91, in user
    next_url=next_url, prev_url=prev_url)
  File "/home/bshi/miniconda3/lib/python3.6/site-packages/flask/templating.py", line 135, in render_template
    context, ctx.app)
  File "/home/bshi/miniconda3/lib/python3.6/site-packages/flask/templating.py", line 117, in _render
    rv = template.render(context)
  File "/home/bshi/miniconda3/lib/python3.6/site-packages/jinja2/asyncsupport.py", line 76, in render
    return original_render(self, *args, **kwargs)
  File "/home/bshi/miniconda3/lib/python3.6/site-packages/jinja2/environment.py", line 1008, in render
    return self.environment.handle_exception(exc_info, True)
  File "/home/bshi/miniconda3/lib/python3.6/site-packages/jinja2/environment.py", line 780, in handle_exception
    reraise(exc_type, exc_value, tb)
  File "/home/bshi/miniconda3/lib/python3.6/site-packages/jinja2/_compat.py", line 37, in reraise
    raise value.with_traceback(tb)
  File "/mnt/c/Users/Bobby Shi/projects/mangalert/app/templates/user.html", line 1, in top-level template code
    {% extends "base.html" %}
  File "/mnt/c/Users/Bobby Shi/projects/mangalert/app/templates/base.html", line 34, in top-level template code
    {% block content %}{% endblock %}
  File "/mnt/c/Users/Bobby Shi/projects/mangalert/app/templates/user.html", line 20, in block "content"
    {{ form.hidden_tag() }}
  File "/home/bshi/miniconda3/lib/python3.6/site-packages/jinja2/environment.py", line 430, in getattr
    return getattr(obj, attribute)
jinja2.exceptions.UndefinedError: 'form' is undefined
2018-09-18 18:12:28,591 INFO: Microblog startup [in /mnt/c/Users/Bobby Shi/projects/mangalert/app/__init__.py:46]
2018-09-18 20:33:39,653 INFO: Microblog startup [in /mnt/c/Users/Bobby Shi/projects/mangalert/app/__init__.py:48]
2018-09-18 20:34:07,625 INFO: Microblog startup [in /mnt/c/Users/Bobby Shi/projects/mangalert/app/__init__.py:48]
2018-09-18 20:34:23,760 INFO: Microblog startup [in /mnt/c/Users/Bobby Shi/projects/mangalert/app/__init__.py:48]
2018-09-18 20:34:40,530 INFO: Microblog startup [in /mnt/c/Users/Bobby Shi/projects/mangalert/app/__init__.py:48]
2018-09-18 20:35:05,942 INFO: Microblog startup [in /mnt/c/Users/Bobby Shi/projects/mangalert/app/__init__.py:48]
